Workbook

Sheet Posts
A1: Post ID | B1: Platform | C1: Date | D1: Content Type | E1: Post Text | F1: Likes | G1: Shares | H1: Comments | I1: Impressions | J1: Reach | K1: Clicks | L1: Hashtags Used | M1: Campaign_Name
A2: P001 | B2: Twitter | C2: 45649 | D2: Reel | E2: Check out our latest reel on twitter! | F2: 1461 | G2: 184 | H2: 344 | I2: 21915 | J2: 21675 | K2: 15 | L2: #FutureOfDriving | M2: CybertruckLaunch
A3: P001 | B3: Twitter | C3: 45649 | D3: Reel | E3: Check out our latest reel on twitter! | F3: 1461 | G3: 184 | H3: 344 | I3: 21915 | J3: 21675 | K3: 15 | L3: #AnytimeIsTeslaTime | M3: CybertruckLaunch
A4: P002 | B4: Twitter | C4: 45750 | D4: Text | E4: Check out our latest text on twitter! | F4: 4054 | G4: 389 | H4: 493 | I4: 64864 | J4: 64383 | K4: 117 | L4: #TeslaCoInnovation | M4: ModelYCampaign
A5: P002 | B5: Twitter | C5: 45750 | D5: Text | E5: Check out our latest text on twitter! | F5: 4054 | G5: 389 | H5: 493 | I5: 64864 | J5: 64383 | K5: 117 | L5: #BetterWithTesla | M5: ModelYCampaign
A6: P003 | B6: YouTube | C6: 45789 | D6: Reel | E6: Check out our latest reel on youtube! | F6: 2795 | G6: 105 | H6: 49 | I6: 53105 | J6: 52307 | K6: 204 | L6: #TeslaCoInnovation | M6: FSDUpdate
A7: P004 | B7: Instagram | C7: 45516 | D7: Story | E7: Check out our latest story on instagram! | F7: 2404 | G7: 363 | H7: 138 | I7: 19232 | J7: 18636 | K7: 128 | L7: #EVRevolution | M7: SustainabilityDrive
A8: P005 | B8: YouTube | C8: 45469 | D8: Reel | E8: Check out our latest reel on youtube! | F8: 3557 | G8: 687 | H8: 424 | I8: 71140 | J8: 70701 | K8: 224 | L8: #EVRevolution | M8: CybertruckLaunch
A9: P005 | B9: YouTube | C9: 45469 | D9: Reel | E9: Check out our latest reel on youtube! | F9: 3557 | G9: 687 | H9: 424 | I9: 71140 | J9: 70701 | K9: 224 | L9: #TeslaCoInnovation | M9: CybertruckLaunch
A10: P006 | B10: Facebook | C10: 45596 | D10: Carousel | E10: Check out our latest carousel on facebook! | F10: 2945 | G10: 930 | H10: 355 | I10: 23560 | J10: 23275 | K10: 256 | L10: #TeslaCoInnovation | M10: ModelYCampaign
A11: P007 | B11: Twitter | C11: 45467 | D11: Carousel | E11: Check out our latest carousel on twitter! | F11: 3860 | G11: 201 | H11: 279 | I11: 61760 | J11: 61660 | K11: 235 | L11: #TeslaCoInnovation | M11: ModelYCampaign
A12: P008 | B12: YouTube | C12: 45486 | D12: Image | E12: Check out our latest image on youtube! | F12: 3929 | G12: 262 | H12: 278 | I12: 43219 | J12: 42841 | K12: 39 | L12: #EVRevolution | M12: SustainabilityDrive
A13: P009 | B13: Facebook | C13: 45534 | D13: Text | E13: Check out our latest text on facebook! | F13: 3784 | G13: 808 | H13: 404 | I13: 56760 | J13: 56343 | K13: 131 | L13: #TeslaCoInnovation | M13: ModelYCampaign
... A17: P013 | B17: YouTube | C17: 45614 | D17: Carousel | E17: Check out our latest carousel on youtube! | F17: 1171 | G17: 286 | H17: 231 | I17: 22249 | J17: 21282 | K17: 114 | L17: #EVRevolution | M17: CybertruckLaunch
A18: P014 | B18: Facebook | C18: 45704 | D18: Story | E18: Check out our latest story on facebook! | F18: 4242 | G18: 555 | H18: 131 | I18: 33936 | J18: 33802 | K18: 265 | L18: #FutureOfDriving
A19: P015 | B19: Facebook | C19: 45589 | D19: Video | E19: Check out our latest video on facebook! | F19: 3888 | G19: 604 | H19: 128 | I19: 77760 | J19: 77167 | K19: 20 | L19: #FutureOfDriving | M19: CybertruckLaunch
A20: P016 | B20: Facebook | C20: 45530 | D20: Text | E20: Check out our latest text on facebook! | F20: 3452 | G20: 377 | H20: 360 | I20: 55232 | J20: 55075 | K20: 87 | L20: #FutureOfDriving | M20: FSDUpdate
A21: P017 | B21: Facebook | C21: 45782 | D21: Text | E21: Check out our latest text on facebook! | F21: 4441 | G21: 511 | H21: 70 | I21: 53292 | J21: 53082 | K21: 159 | L21: #EVRevolution | M21: SustainabilityDrive
A22: P018 | B22: Instagram | C22: 45523 | D22: Reel | E22: Check out our latest reel on instagram! | F22: 3000 | G22: 382 | H22: 325 | I22: 36000 | J22: 35819 | K22: 19 | L22: #FutureOfDriving | M22: CybertruckLaunch
A23: P019 | B23: Instagram | C23: 45466 | D23: Video | E23: Check out our latest video on instagram! | F23: 1071 | G23: 519 | H23: 22 | I23: 16065 | J23: 15865 | K23: 103 | L23: #TeslaCoInnovation | M23: SustainabilityDrive
A24: P020 | B24: Instagram | C24: 45544 | D24: Carousel | E24: Check out our latest carousel on instagram! | F24: 4054 | G24: 488 | H24: 373 | I24: 77026 | J24: 76881 | K24: 25 | L24: #TeslaCoInnovation | M24: CybertruckLaunch
A25: P021 | B25: Instagram | C25: 45661 | D25: Reel | E25: Check out our latest reel on instagram! | F25: 4838 | G25: 640 | H25: 128 | I25: 72570 | J25: 72396 | K25: 83 | L25: #FutureOfDriving | M25: SustainabilityDrive
A26: P022 | B26: Facebook | C26: 45715 | D26: Text | E26: Check out our latest text on facebook! | F26: 1570 | G26: 187 | H26: 260 | I26: 25120 | J26: 24613 | K26: 133 | L26: #TeslaCoInnovation | M26: SustainabilityDrive
A27: P023 | B27: Facebook | C27: 45602 | D27: Video | E27: Check out our latest video on facebook! | F27: 1606 | G27: 547 | H27: 316 | I27: 32120 | J27: 31736 | K27: 225 | L27: #TeslaCoInnovation | M27: ModelYCampaign
A28: P023 | B28: Facebook | C28: 45602 | D28: Video | E28: Check out our latest video on facebook! | F28: 1606 | G28: 547 | H28: 316 | I28: 32120 | J28: 31736 | K28: 225 | L28: #AnytimeIsTeslaTime | M28: ModelYCampaign
A29: P024 | B29: Facebook | C29: 45680 | D29: Video | E29: Check out our latest video on facebook! | F29: 3961 | G29: 761 | H29: 131 | I29: 67337 | J29: 66615 | K29: 161 | L29: #FutureOfDriving | M29: FSDUpdate
A30: P025 | B30: Twitter | C30: 45757 | D30: Carousel | E30: Check out our latest carousel on twitter! | F30: 3128 | G30: 211 | H30: 197 | I30: 59432 | J30: 59182 | K30: 238 | L30: #EVRevolution
A31: P026 | B31: YouTube | C31: 45752 | D31: Reel | E31: Check out our latest reel on youtube! | F31: 3009 | G31: 413 | H31: 358 | I31: 42126 | J31: 41309 | K31: 211 | L31: #FutureOfDriving | M31: ModelYCampaign
A32: P027 | B32: YouTube | C32: 45552 | D32: Text | E32: Check out our latest text on youtube! | F32: 2076 | G32: 195 | H32: 104 | I32: 33216 | J32: 32244 | K32: 51 | L32: #FutureOfDriving | M32: SustainabilityDrive
A33: P028 | B33: Instagram | C33: 45720 | D33: Video | E33: Check out our latest video on instagram! | F33: 432 | G33: 624 | H33: 123 | I33: 6912 | J33: 6259 | K33: 79 | L33: #FutureOfDriving | M33: SustainabilityDrive
A34: P029 | B34: Instagram | C34: 45688 | D34: Carousel | E34: Check out our latest carousel on instagram! | F34: 2566 | G34: 118 | H34: 37 | I34: 12830 | J34: 12264 | K34: 221 | L34: #FutureOfDriving | M34: FSDUpdate
A35: P030 | B35: Instagram | C35: 45713 | D35: Video | E35: Check out our latest video on instagram! | F35: 3095 | G35: 39 | H35: 78 | I35: 55710 | J35: 54808 | K35: 93 | L35: #EVRevolution
A36: P031 | B36: Instagram | C36: 45642 | D36: Text | E36: Check out our latest text on instagram! | F36: 438 | G36: 153 | H36: 275 | I36: 3066 | J36: 2701 | K36: 282 | L36: #TeslaCoInnovation | M36: ModelYCampaign
A37: P032 | B37: Twitter | C37: 45504 | D37: Carousel | E37: Check out our latest carousel on twitter! | F37: 2278 | G37: 10 | H37: 321 | I37: 13668 | J37: 12676 | K37: 275 | L37: #EVRevolution | M37: CybertruckLaunch
A38: P033 | B38: Facebook | C38: 45525 | D38: Image | E38: Check out our latest image on facebook! | F38: 1407 | G38: 400 | H38: 351 | I38: 16884 | J38: 15954 | K38: 113 | L38: #TeslaCoInnovation | M38: CybertruckLaunch
A39: P034 | B39: Facebook | C39: 45742 | D39: Text | E39: Check out our latest text on facebook! | F39: 1652 | G39: 89 | H39: 357 | I39: 29736 | J39: 28771 | K39: 215 | L39: #TeslaCoInnovation | M39: FSDUpdate
A40: P035 | B40: Instagram | C40: 45626 | D40: Video | E40: Check out our latest video on instagram! | F40: 3775 | G40: 16 | H40: 239 | I40: 33975 | J40: 33310 | K40: 271 | L40: #FutureOfDriving | M40: ModelYCampaign
A41: P036 | B41: Instagram | C41: 45766 | D41: Story | E41: Check out our latest story on instagram! | F41: 4518 | G41: 285 | H41: 383 | I41: 67770 | J41: 67621 | K41: 31 | L41: #EVRevolution | M41: ModelYCampaign
A42: P037 | B42: Facebook | C42: 45663 | D42: Carousel | E42: Check out our latest carousel on facebook! | F42: 3024 | G42: 925 | H42: 350 | I42: 24192 | J42: 23518 | K42: 36 | L42: #EVRevolution | M42: ModelYCampaign
A43: P038 | B43: YouTube | C43: 45705 | D43: Reel | E43: Check out our latest reel on youtube! | F43: 3138 | G43: 123 | H43: 291 | I43: 28242 | J43: 27550 | K43: 87 | L43: #TeslaCoInnovation | M43: SustainabilityDrive
...

Sheet Engagement Summary
A1: Week_Start_Date | B1: Platform | C1: New_Followers | D1: Unfollows | E1: Total_Followers | F1: Engagement_Rate | G1: Ad_Spend | H1: Net Growth Followers | I1: Growth Rate | J1: Campaign Name
A2: 45446 | B2: Instagram | C2: 1135 | D2: 88 | E2: 344084 | F2: 8.06 | G2: 5904 | H2: =Engagement_Summary[[#This Row],[New_Followers]]-Engagement_Summary[[#This Row],[Unfollows]] -> 1047 | I2: =Engagement_Summary[[#This Row],[Net Growth Followers]]/Engagement_Summary[[#This Row],[Total_Followers]] -> 0.0030428616 | J2: =_xlfn.XLOOKUP(Engagement_Summary[[#This Row],[Week_Start_Date]],Task1!C:C,Task1!M:M,"NA",-1) -> SustainabilityDrive
A3: 45446 | B3: Facebook | C3: 1312 | D3: 310 | E3: 42654 | F3: 4.98 | G3: 9566 | H3: =Engagement_Summary[[#This Row],[New_Followers]]-Engagement_Summary[[#This Row],[Unfollows]] -> 1002 | I3: =Engagement_Summary[[#This Row],[Net Growth Followers]]/Engagement_Summary[[#This Row],[Total_Followers]] -> 0.023491349 | J3: =_xlfn.XLOOKUP(Engagement_Summary[[#This Row],[Week_Start_Date]],Task1!C:C,Task1!M:M,"NA",-1) -> SustainabilityDrive
A4: 45446 | B4: Twitter | C4: 584 | D4: 169 | E4: 146834 | F4: 8.31 | G4: 26752 | H4: =Engagement_Summary[[#This Row],[New_Followers]]-Engagement_Summary[[#This Row],[Unfollows]] -> 415 | I4: =Engagement_Summary[[#This Row],[Net Growth Followers]]/Engagement_Summary[[#This Row],[Total_Followers]] -> 0.0028263209 | J4: =_xlfn.XLOOKUP(Engagement_Summary[[#This Row],[Week_Start_Date]],Task1!C:C,Task1!M:M,"NA",-1) -> SustainabilityDrive
A5: 45446 | B5: YouTube | C5: 1535 | D5: 445 | E5: 395536 | F5: 4.11 | G5: 30671 | H5: =Engagement_Summary[[#This Row],[New_Followers]]-Engagement_Summary[[#This Row],[Unfollows]] -> 1090 | I5: =Engagement_Summary[[#This Row],[Net Growth Followers]]/Engagement_Summary[[#This Row],[Total_Followers]] -> 0.0027557542 | J5: =_xlfn.XLOOKUP(Engagement_Summary[[#This Row],[Week_Start_Date]],Task1!C:C,Task1!M:M,"NA",-1) -> SustainabilityDrive
A6: 45453 | B6: Instagram | C6: 656 | D6: 139 | E6: 49157 | F6: 9.05 | G6: 9920 | H6: =Engagement_Summary[[#This Row],[New_Followers]]-Engagement_Summary[[#This Row],[Unfollows]] -> 517 | I6: =Engagement_Summary[[#This Row],[Net Growth Followers]]/Engagement_Summary[[#This Row],[Total_Followers]] -> 0.010517322 | J6: =_xlfn.XLOOKUP(Engagement_Summary[[#This Row],[Week_Start_Date]],Task1!C:C,Task1!M:M,"NA",-1) -> SustainabilityDrive
A7: 45453 | B7: Facebook | C7: 1697 | D7: 414 | E7: 316555 | F7: 2.37 | G7: 7924 | H7: =Engagement_Summary[[#This Row],[New_Followers]]-Engagement_Summary[[#This Row],[Unfollows]] -> 1283 | I7: =Engagement_Summary[[#This Row],[Net Growth Followers]]/Engagement_Summary[[#This Row],[Total_Followers]] -> 0.0040530082 | J7: =_xlfn.XLOOKUP(Engagement_Summary[[#This Row],[Week_Start_Date]],Task1!C:C,Task1!M:M,"NA",-1) -> SustainabilityDrive
A8: 45453 | B8: Twitter | C8: 436 | D8: 250 | E8: 254347 | F8: 4.01 | G8: 8912 | H8: =Engagement_Summary[[#This Row],[New_Followers]]-Engagement_Summary[[#This Row],[Unfollows]] -> 186 | I8: =Engagement_Summary[[#This Row],[Net Growth Followers]]/Engagement_Summary[[#This Row],[Total_Followers]] -> 0.00073128443 | J8: =_xlfn.XLOOKUP(Engagement_Summary[[#This Row],[Week_Start_Date]],Task1!C:C,Task1!M:M,"NA",-1) -> SustainabilityDrive
A9: 45453 | B9: YouTube | C9: 1197 | D9: 203 | E9: 413878 | F9: 3.16 | G9: 21205 | H9: =Engagement_Summary[[#This Row],[New_Followers]]-Engagement_Summary[[#This Row],[Unfollows]] -> 994 | I9: =Engagement_Summary[[#This Row],[Net Growth Followers]]/Engagement_Summary[[#This Row],[Total_Followers]] -> 0.0024016739 | J9: =_xlfn.XLOOKUP(Engagement_Summary[[#This Row],[Week_Start_Date]],Task1!C:C,Task1!M:M,"NA",-1) -> SustainabilityDrive
A10: 45460 | B10: Instagram | C10: 1048 | D10: 155 | E10: 456946 | F10: 2.46 | G10: 11329 | H10: =Engagement_Summary[[#This Row],[New_Followers]]-Engagement_Summary[[#This Row],[Unfollows]] -> 893 | I10: =Engagement_Summary[[#This Row],[Net Growth Followers]]/Engagement_Summary[[#This Row],[Total_Followers]] -> 0.0019542791 | J10: =_xlfn.XLOOKUP(Engagement_Summary[[#This Row],[Week_Start_Date]],Task1!C:C,Task1!M:M,"NA",-1) -> SustainabilityDrive
A11: 45460 | B11: Facebook | C11: 1753 | D11: 371 | E11: 169496 | F11: 8.11 | G11: 46670 | H11: =Engagement_Summary[[#This Row],[New_Followers]]-Engagement_Summary[[#This Row],[Unfollows]] -> 1382 | I11: =Engagement_Summary[[#This Row],[Net Growth Followers]]/Engagement_Summary[[#This Row],[Total_Followers]] -> 0.0081535847 | J11: =_xlfn.XLOOKUP(Engagement_Summary[[#This Row],[Week_Start_Date]],Task1!C:C,Task1!M:M,"NA",-1) -> SustainabilityDrive
A12: 45460 | B12: Twitter | C12: 1335 | D12: 40 | E12: 122732 | F12: 8.19 | G12: 22482 | H12: =Engagement_Summary[[#This Row],[New_Followers]]-Engagement_Summary[[#This Row],[Unfollows]] -> 1295 | I12: =Engagement_Summary[[#This Row],[Net Growth Followers]]/Engagement_Summary[[#This Row],[Total_Followers]] -> 0.010551445 | J12: =_xlfn.XLOOKUP(Engagement_Summary[[#This Row],[Week_Start_Date]],Task1!C:C,Task1!M:M,"NA",-1) -> SustainabilityDrive
A13: 45460 | B13: YouTube | C13: 403 | D13: 66 | E13: 382851 | F13: 3.49 | G13: 24313 | H13: =Engagement_Summary[[#This Row],[New_Followers]]-Engagement_Summary[[#This Row],[Unfollows]] -> 337 | I13: =Engagement_Summary[[#This Row],[Net Growth Followers]]/Engagement_Summary[[#This Row],[Total_Followers]] -> 0.000880238 | J13: =_xlfn.XLOOKUP(Engagement_Summary[[#This Row],[Week_Start_Date]],Task1!C:C,Task1!M:M,"NA",-1) -> SustainabilityDrive
... A201: 45789 | B201: YouTube | C201: 119 | D201: 456 | E201: 82558 | F201: 6.81 | G201: 12174 | H201: =Engagement_Summary[[#This Row],[New_Followers]]-Engagement_Summary[[#This Row],[Unfollows]] -> -337 | I201: =Engagement_Summary[[#This Row],[Net Growth Followers]]/Engagement_Summary[[#This Row],[Total_Followers]] -> -0.0040819787 | J201: =_xlfn.XLOOKUP(Engagement_Summary[[#This Row],[Week_Start_Date]],Task1!C:C,Task1!M:M,"NA",-1) -> FSDUpdate

Sheet Campaign Metadata
A1: Campaign_Name | B1: Start_Date | C1: End_Date | D1: Objective | E1: Total_Budget | F1: Target_Platforms | G1: Primary_Hashtags
A2: CybertruckLaunch | B2: 45458 | C2: 45488 | D2: Product Awareness | E2: 150000 | F2: Instagram,Facebook | G2: #EVRevolution,#TeslaCoInnovation
A3: ModelYCampaign | B3: 45566 | C3: 45596 | D3: Customer Engagement | E3: 200000 | F3: Instagram,YouTube | G3: #AnytimeIsTeslaTime,
A4: FSDUpdate | B4: 45651 | C4: 45667 | D4: Vehicle Launch | E4: 250000 | F4: Facebook,Twitter | G4: #SmoothLikeNitroTesla
A5: SustainabilityDrive | B5: 45717 | C5: 45747 | D5: Community Growth | E5: 180000 | F5: Instagram,Twitter | G5: #BetterWithTesla,#FutureOfDriving

Sheet Task1
A1: Post ID | B1: Platform | C1: Date | D1: Content Type | E1: Post Text | F1: Likes | G1: Shares | H1: Comments | I1: Impressions | J1: Reach | K1: Clicks | L1: Hashtags Used | M1: Campaign_Name | N1: Engagement Rate | O1: Engagement | P1: Ad Spend | Q1: Period | R1: ROI
A2: P001 | B2: Twitter | C2: 45649 | D2: Reel | E2: Check out our latest reel on twitter! | F2: 1461 | G2: 184 | H2: 344 | I2: 21915 | J2: 21675 | K2: 15 | L2: #FutureOfDriving | M2: CybertruckLaunch | N2: =(Posts__2[[#This Row],[Likes]]+Posts__2[[#This Row],[Shares]]+Posts__2[[#This Row],[Comments]])/Posts__2[[#This Row],[Impressions]] -> 0.090759754 | O2: =Posts__2[[#This Row],[Likes]]+Posts__2[[#This Row],[Shares]]+Posts__2[[#This Row],[Comments]] -> 1989 | P2: =_xlfn.XLOOKUP(Posts__2[[#This Row],[Platform]],'Engagement Summary'!B:B,'Engagement Summary'!G:G,"NA",0) -> 26752 | Q2: =IFERROR(IF(C2 < _xlfn.XLOOKUP(M2, 'Campaign Metadata'!A:A, 'Campaign Metadata'!B:B), "Before", "During"), "Not Found") -> During | R2: =Posts__2[[#This Row],[Engagement]]/Posts__2[[#This Row],[Ad Spend]] -> 0.074349581
A3: P001 | B3: Twitter | C3: 45649 | D3: Reel | E3: Check out our latest reel on twitter! | F3: 1461 | G3: 184 | H3: 344 | I3: 21915 | J3: 21675 | K3: 15 | L3: #AnytimeIsTeslaTime | M3: CybertruckLaunch | N3: =(Posts__2[[#This Row],[Likes]]+Posts__2[[#This Row],[Shares]]+Posts__2[[#This Row],[Comments]])/Posts__2[[#This Row],[Impressions]] -> 0.090759754 | O3: =Posts__2[[#This Row],[Likes]]+Posts__2[[#This Row],[Shares]]+Posts__2[[#This Row],[Comments]] -> 1989 | P3: =_xlfn.XLOOKUP(Posts__2[[#This Row],[Platform]],'Engagement Summary'!B:B,'Engagement Summary'!G:G,"NA",0) -> 26752 | Q3: =IFERROR(IF(C3 < _xlfn.XLOOKUP(M3, 'Campaign Metadata'!A:A, 'Campaign Metadata'!B:B), "Before", "During"), "Not Found") -> During | R3: =Posts__2[[#This Row],[Engagement]]/Posts__2[[#This Row],[Ad Spend]] -> 0.074349581
A4: P002 | B4: Twitter | C4: 45750 | D4: Text | E4: Check out our latest text on twitter! | F4: 4054 | G4: 389 | H4: 493 | I4: 64864 | J4: 64383 | K4: 117 | L4: #TeslaCoInnovation | M4: ModelYCampaign | N4: =(Posts__2[[#This Row],[Likes]]+Posts__2[[#This Row],[Shares]]+Posts__2[[#This Row],[Comments]])/Posts__2[[#This Row],[Impressions]] -> 0.076097681 | O4: =Posts__2[[#This Row],[Likes]]+Posts__2[[#This Row],[Shares]]+Posts__2[[#This Row],[Comments]] -> 4936 | P4: =_xlfn.XLOOKUP(Posts__2[[#This Row],[Platform]],'Engagement Summary'!B:B,'Engagement Summary'!G:G,"NA",0) -> 26752 | Q4: =IFERROR(IF(C4 < _xlfn.XLOOKUP(M4, 'Campaign Metadata'!A:A, 'Campaign Metadata'!B:B), "Before", "During"), "Not Found") -> During | R4: =Posts__2[[#This Row],[Engagement]]/Posts__2[[#This Row],[Ad Spend]] -> 0.18450957
A5: P002 | B5: Twitter | C5: 45750 | D5: Text | E5: Check out our latest text on twitter! | F5: 4054 | G5: 389 | H5: 493 | I5: 64864 | J5: 64383 | K5: 117 | L5: #BetterWithTesla | M5: ModelYCampaign | N5: =(Posts__2[[#This Row],[Likes]]+Posts__2[[#This Row],[Shares]]+Posts__2[[#This Row],[Comments]])/Posts__2[[#This Row],[Impressions]] -> 0.076097681 | O5: =Posts__2[[#This Row],[Likes]]+Posts__2[[#This Row],[Shares]]+Posts__2[[#This Row],[Comments]] -> 4936 | P5: =_xlfn.XLOOKUP(Posts__2[[#This Row],[Platform]],'Engagement Summary'!B:B,'Engagement Summary'!G:G,"NA",0) -> 26752 | Q5: =IFERROR(IF(C5 < _xlfn.XLOOKUP(M5, 'Campaign Metadata'!A:A, 'Campaign Metadata'!B:B), "Before", "During"), "Not Found") -> During | R5: =Posts__2[[#This Row],[Engagement]]/Posts__2[[#This Row],[Ad Spend]] -> 0.18450957
A6: P003 | B6: YouTube | C6: 45789 | D6: Reel | E6: Check out our latest reel on youtube! | F6: 2795 | G6: 105 | H6: 49 | I6: 53105 | J6: 52307 | K6: 204 | L6: #TeslaCoInnovation | M6: FSDUpdate | N6: =(Posts__2[[#This Row],[Likes]]+Posts__2[[#This Row],[Shares]]+Posts__2[[#This Row],[Comments]])/Posts__2[[#This Row],[Impressions]] -> 0.055531494 | O6: =Posts__2[[#This Row],[Likes]]+Posts__2[[#This Row],[Shares]]+Posts__2[[#This Row],[Comments]] -> 2949 | P6: =_xlfn.XLOOKUP(Posts__2[[#This Row],[Platform]],'Engagement Summary'!B:B,'Engagement Summary'!G:G,"NA",0) -> 30671 | Q6: =IFERROR(IF(C6 < _xlfn.XLOOKUP(M6, 'Campaign Metadata'!A:A, 'Campaign Metadata'!B:B), "Before", "During"), "Not Found") -> During | R6: =Posts__2[[#This Row],[Engagement]]/Posts__2[[#This Row],[Ad Spend]] -> 0.096149457
A7: P004 | B7: Instagram | C7: 45516 | D7: Story | E7: Check out our latest story on instagram! | F7: 2404 | G7: 363 | H7: 138 | I7: 19232 | J7: 18636 | K7: 128 | L7: #EVRevolution | M7: SustainabilityDrive | N7: =(Posts__2[[#This Row],[Likes]]+Posts__2[[#This Row],[Shares]]+Posts__2[[#This Row],[Comments]])/Posts__2[[#This Row],[Impressions]] -> 0.15105033 | O7: =Posts__2[[#This Row],[Likes]]+Posts__2[[#This Row],[Shares]]+Posts__2[[#This Row],[Comments]] -> 2905 | P7: =_xlfn.XLOOKUP(Posts__2[[#This Row],[Platform]],'Engagement Summary'!B:B,'Engagement Summary'!G:G,"NA",0) -> 5904 | Q7: =IFERROR(IF(C7 < _xlfn.XLOOKUP(M7, 'Campaign Metadata'!A:A, 'Campaign Metadata'!B:B), "Before", "During"), "Not Found") -> Before | R7: =Posts__2[[#This Row],[Engagement]]/Posts__2[[#This Row],[Ad Spend]] -> 0.4920393
A8: P005 | B8: YouTube | C8: 45469 | D8: Reel | E8: Check out our latest reel on youtube! | F8: 3557 | G8: 687 | H8: 424 | I8: 71140 | J8: 70701 | K8: 224 | L8: #EVRevolution | M8: CybertruckLaunch | N8: =(Posts__2[[#This Row],[Likes]]+Posts__2[[#This Row],[Shares]]+Posts__2[[#This Row],[Comments]])/Posts__2[[#This Row],[Impressions]] -> 0.065617093 | O8: =Posts__2[[#This Row],[Likes]]+Posts__2[[#This Row],[Shares]]+Posts__2[[#This Row],[Comments]] -> 4668 | P8: =_xlfn.XLOOKUP(Posts__2[[#This Row],[Platform]],'Engagement Summary'!B:B,'Engagement Summary'!G:G,"NA",0) -> 30671 | Q8: =IFERROR(IF(C8 < _xlfn.XLOOKUP(M8, 'Campaign Metadata'!A:A, 'Campaign Metadata'!B:B), "Before", "During"), "Not Found") -> During | R8: =Posts__2[[#This Row],[Engagement]]/Posts__2[[#This Row],[Ad Spend]] -> 0.15219589
A9: P005 | B9: YouTube | C9: 45469 | D9: Reel | E9: Check out our latest reel on youtube! | F9: 3557 | G9: 687 | H9: 424 | I9: 71140 | J9: 70701 | K9: 224 | L9: #TeslaCoInnovation | M9: CybertruckLaunch | N9: =(Posts__2[[#This Row],[Likes]]+Posts__2[[#This Row],[Shares]]+Posts__2[[#This Row],[Comments]])/Posts__2[[#This Row],[Impressions]] -> 0.065617093 | O9: =Posts__2[[#This Row],[Likes]]+Posts__2[[#This Row],[Shares]]+Posts__2[[#This Row],[Comments]] -> 4668 | P9: =_xlfn.XLOOKUP(Posts__2[[#This Row],[Platform]],'Engagement Summary'!B:B,'Engagement Summary'!G:G,"NA",0) -> 30671 | Q9: =IFERROR(IF(C9 < _xlfn.XLOOKUP(M9, 'Campaign Metadata'!A:A, 'Campaign Metadata'!B:B), "Before", "During"), "Not Found") -> During | R9: =Posts__2[[#This Row],[Engagement]]/Posts__2[[#This Row],[Ad Spend]] -> 0.15219589
A10: P006 | B10: Facebook | C10: 45596 | D10: Carousel | E10: Check out our latest carousel on facebook! | F10: 2945 | G10: 930 | H10: 355 | I10: 23560 | J10: 23275 | K10: 256 | L10: #TeslaCoInnovation | M10: ModelYCampaign | N10: =(Posts__2[[#This Row],[Likes]]+Posts__2[[#This Row],[Shares]]+Posts__2[[#This Row],[Comments]])/Posts__2[[#This Row],[Impressions]] -> 0.1795416 | O10: =Posts__2[[#This Row],[Likes]]+Posts__2[[#This Row],[Shares]]+Posts__2[[#This Row],[Comments]] -> 4230 | P10: =_xlfn.XLOOKUP(Posts__2[[#This Row],[Platform]],'Engagement Summary'!B:B,'Engagement Summary'!G:G,"NA",0) -> 9566 | Q10: =IFERROR(IF(C10 < _xlfn.XLOOKUP(M10, 'Campaign Metadata'!A:A, 'Campaign Metadata'!B:B), "Before", "During"), "Not Found") -> During | R10: =Posts__2[[#This Row],[Engagement]]/Posts__2[[#This Row],[Ad Spend]] -> 0.44219109
A11: P007 | B11: Twitter | C11: 45467 | D11: Carousel | E11: Check out our latest carousel on twitter! | F11: 3860 | G11: 201 | H11: 279 | I11: 61760 | J11: 61660 | K11: 235 | L11: #TeslaCoInnovation | M11: ModelYCampaign | N11: =(Posts__2[[#This Row],[Likes]]+Posts__2[[#This Row],[Shares]]+Posts__2[[#This Row],[Comments]])/Posts__2[[#This Row],[Impressions]] -> 0.070272021 | O11: =Posts__2[[#This Row],[Likes]]+Posts__2[[#This Row],[Shares]]+Posts__2[[#This Row],[Comments]] -> 4340 | P11: =_xlfn.XLOOKUP(Posts__2[[#This Row],[Platform]],'Engagement Summary'!B:B,'Engagement Summary'!G:G,"NA",0) -> 26752 | Q11: =IFERROR(IF(C11 < _xlfn.XLOOKUP(M11, 'Campaign Metadata'!A:A, 'Campaign Metadata'!B:B), "Before", "During"), "Not Found") -> Before | R11: =Posts__2[[#This Row],[Engagement]]/Posts__2[[#This Row],[Ad Spend]] -> 0.16223086
A12: P008 | B12: YouTube | C12: 45486 | D12: Image | E12: Check out our latest image on youtube! | F12: 3929 | G12: 262 | H12: 278 | I12: 43219 | J12: 42841 | K12: 39 | L12: #EVRevolution | M12: SustainabilityDrive | N12: =(Posts__2[[#This Row],[Likes]]+Posts__2[[#This Row],[Shares]]+Posts__2[[#This Row],[Comments]])/Posts__2[[#This Row],[Impressions]] -> 0.1034036 | O12: =Posts__2[[#This Row],[Likes]]+Posts__2[[#This Row],[Shares]]+Posts__2[[#This Row],[Comments]] -> 4469 | P12: =_xlfn.XLOOKUP(Posts__2[[#This Row],[Platform]],'Engagement Summary'!B:B,'Engagement Summary'!G:G,"NA",0) -> 30671 | Q12: =IFERROR(IF(C12 < _xlfn.XLOOKUP(M12, 'Campaign Metadata'!A:A, 'Campaign Metadata'!B:B), "Before", "During"), "Not Found") -> Before | R12: =Posts__2[[#This Row],[Engagement]]/Posts__2[[#This Row],[Ad Spend]] -> 0.14570767
A13: P009 | B13: Facebook | C13: 45534 | D13: Text | E13: Check out our latest text on facebook! | F13: 3784 | G13: 808 | H13: 404 | I13: 56760 | J13: 56343 | K13: 131 | L13: #TeslaCoInnovation | M13: ModelYCampaign | N13: =(Posts__2[[#This Row],[Likes]]+Posts__2[[#This Row],[Shares]]+Posts__2[[#This Row],[Comments]])/Posts__2[[#This Row],[Impressions]] -> 0.088019732 | O13: =Posts__2[[#This Row],[Likes]]+Posts__2[[#This Row],[Shares]]+Posts__2[[#This Row],[Comments]] -> 4996 | P13: =_xlfn.XLOOKUP(Posts__2[[#This Row],[Platform]],'Engagement Summary'!B:B,'Engagement Summary'!G:G,"NA",0) -> 9566 | Q13: =IFERROR(IF(C13 < _xlfn.XLOOKUP(M13, 'Campaign Metadata'!A:A, 'Campaign Metadata'!B:B), "Before", "During"), "Not Found") -> Before | R13: =Posts__2[[#This Row],[Engagement]]/Posts__2[[#This Row],[Ad Spend]] -> 0.52226636
... A340: P300 | B340: Twitter | C340: 45535 | D340: Carousel | E340: Check out our latest carousel on twitter! | F340: 4494 | G340: 717 | H340: 45 | I340: 62916 | J340: 62688 | K340: 191 | L340: #BetterWithTesla | M340: CybertruckLaunch | N340: =(Posts__2[[#This Row],[Likes]]+Posts__2[[#This Row],[Shares]]+Posts__2[[#This Row],[Comments]])/Posts__2[[#This Row],[Impressions]] -> 0.083539958 | O340: =Posts__2[[#This Row],[Likes]]+Posts__2[[#This Row],[Shares]]+Posts__2[[#This Row],[Comments]] -> 5256 | P340: =_xlfn.XLOOKUP(Posts__2[[#This Row],[Platform]],'Engagement Summary'!B:B,'Engagement Summary'!G:G,"NA",0) -> 26752 | Q340: =IFERROR(IF(C340 < _xlfn.XLOOKUP(M340, 'Campaign Metadata'!A:A, 'Campaign Metadata'!B:B), "Before", "During"), "Not Found") -> During | R340: =Posts__2[[#This Row],[Engagement]]/Posts__2[[#This Row],[Ad Spend]] -> 0.19647129

Sheet Task2
A1: Engagement Rate per Platform
A3: Row Labels | B3: Avg Engagement Rate
A4: Instagram | B4: 0.18531785
A5: Twitter | B5: 0.13739369
A6: YouTube | B6: 0.13298735
A7: Facebook | B7: 0.12094203
A8: #Insights : Instagram have the highest engagement rate
A14: Top 10 Tesla posts with highest engagement
A17: Row Labels | B17: Sum of Engagement
A18: P280 | B18: 16020
A19: P260 | B19: 15966
A20: P300 | B20: 15768
A21: P247 | B21: 12702
A22: P164 | B22: 12122
A23: P257 | B23: 11853
A24: P097 | B24: 10802
A25: P002 | B25: 9872
A26: P207 | B26: 9790
A27: P205 | B27: 9570
A28: #Insights : Post ID 280 (YouTube) have the highest engagement
A30: Total Likes, Shares, Comments by Content Type & Platform
A33: Row Labels | B33: Sum of Likes | C33: Sum of Shares | D33: Sum of Comments
A34: Facebook | B34: 265966 | C34: 42720 | D34: 25855
A35: Carousel | B35: 44476 | C35: 7400 | D35: 4589
A36: Image | B36: 80073 | C36: 14376 | D36: 7308
A37: Reel | B37: 46102 | C37: 7149 | D37: 3732
A38: Story | B38: 29405 | C38: 4950 | D38: 3223
A39: Text | B39: 35357 | C39: 5127 | D39: 4424
A40: Video | B40: 30553 | C40: 3718 | D40: 2579
A41: Instagram | B41: 222773 | C41: 46563 | D41: 19898
A42: Carousel | B42: 45776 | C42: 7903 | D42: 4382
A43: Image | B43: 40391 | C43: 5989 | D43: 3646
A44: Reel | B44: 32148 | C44: 8110 | D44: 3386
A45: Story | B45: 51313 | C45: 11591 | D45: 4284
... A61: Video | B61: 39835 | C61: 6946 | D61: 3359
A63: #Insights : Facebook have most likes and comments while Instagram have most shares.
A67: Average Clicks per post by Hashtag
A69: Row Labels | B69: Average of Clicks
A70: #AnytimeIsTeslaTime | B70: 161.2
A71: #TeslaCoInnovation | B71: 158.65421
...

Sheet Task3
A1: Identify the platform with highest engagement
A3: Row Labels | B3: Sum of Engagement
A4: Facebook | B4: 334541
A5: Twitter | B5: 300942
A6: Instagram | B6: 289234
A7: YouTube | B7: 243633
A9: #Insights : Facebook have the highest engagement
A12: Follower growth rates across platforms
A14: Row Labels | B14: Sum of Growth Rate
A15: Twitter | B15: 0.46400128
A16: YouTube | B16: 0.45105333
A17: Instagram | B17: 0.28812661
A18: Facebook | B18: 0.27324953
A19: #Insights : Twitter have the highest follower growth rate
A22: Visualize Engagement vs. Ad Spend per platform.
A25: Row Labels | B25: Average of Ad Spend | C25: Average of Engagement
A26: Facebook | B26: 9566 | C26: 3597.2151
A27: Instagram | B27: 5904 | C27: 3286.75
A28: Twitter | B28: 26752 | C28: 3271.1087
A29: YouTube | B29: 30671 | C29: 3691.4091
A33: Accroding to my analysis Tesla should focus on Twitter + Youtube

Sheet Task4
A1: Identify most frequently used Tesla hashtags.
A3: Row Labels | B3: Count of Hashtags Used
A4: #TeslaCoInnovation | B4: 107
A5: #FutureOfDriving | B5: 103
A6: #EVRevolution | B6: 102
A7: #AnytimeIsTeslaTime | B7: 15
A8: #BetterWithTesla | B8: 7
A9: #SmoothLikeNitroTesla | B9: 5
A10: #Insights : #TeslaColnnovation is the most used hashtags
A13: Average performance of posts containing each hashtag
A15: Row Labels | B15: Average of Engagement
A16: #BetterWithTesla | B16: 4143.2857
A17: #SmoothLikeNitroTesla | B17: 3767.4
A18: #EVRevolution | B18: 3534.7157
A19: #TeslaCoInnovation | B19: 3417.3084
A20: #FutureOfDriving | B20: 3405.8544
A21: #AnytimeIsTeslaTime | B21: 2900.9333
A22: #Insights : #BetterWithTesla hashtag has the best performance.
A26: content performance
A28: Row Labels | B28: Average of Engagement
A29: Story | B29: 3566.5417
A30: Reel | B30: 3479.2453
A31: Video | B31: 3447.3922
A32: Text | B32: 3438.8542
A33: Image | B33: 3414.8472
A34: Carousel | B34: 3373.209
A35: #Insights : Story content has the best performance
A38: Content type performance per platform
A40: Average of Engagement | B40: Column Labels
A41: Row Labels | B41: Carousel | C41: Image | D41: Reel | E41: Story | F41: Text | G41: Video
A42: Facebook | B42: 4033.2143 | C42: 3634.1786 | D42: 4070.2143 | E42: 3416.1818 | F42: 2806.75 | G42: 3685
A43: Instagram | B43: 3055.8421 | C43: 3848.1538 | D43: 3357.2308 | E43: 3536.2105 | F43: 3262.5 | G43: 2692.1429
A44: Twitter | B44: 3470 | C44: 2899.8182 | D44: 2956.75 | E44: 3175.7778 | F44: 3800.5 | G44: 3409.1333
A45: YouTube | B45: 2928.25 | C45: 3365.5556 | D45: 3449.4286 | E45: 4205.1111 | F45: 4192.6 | G45: 4178.3333
A47: #Recommendation of content type per platform : Facebook --> Carousel,Reel, Video Instagram --> Image, Story Twitter --> Text, Carousel Youtube --> Story, Text, Video

Sheet Task 5
A1: Campaign Name | B1: Total impressions | C1: Avg Impressions | D1: Total Likes | E1: Avg Likes | F1: Total Clicks | G1: Avg Clicks
A2: CybertruckLaunch | B2: =SUMIFS(Task1!I:I,Task1!M:M,"CybertruckLaunch") -> 2090555 | C2: =AVERAGEIFS(Task1!I:I,Task1!M:M,"CybertruckLaunch") -> 39444.434 | D2: =SUMIFS(Task1!F:F,Task1!M:M,"CybertruckLaunch") -> 154613 | E2: =AVERAGEIFS(Task1!F:F,Task1!M:M,"CybertruckLaunch") -> 2917.2264 | F2: =SUMIFS(Task1!K:K,Task1!M:M,"CybertruckLaunch") -> 7094 | G2: =AVERAGEIFS(Task1!K:K,Task1!M:M,"CybertruckLaunch") -> 133.84906
A3: ModelYCampaign | B3: =SUMIFS(Task1!I:I,Task1!M:M,"ModelYCampaign") -> 2318527 | C3: =AVERAGEIFS(Task1!I:I,Task1!M:M,"ModelYCampaign") -> 34095.985 | D3: =SUMIFS(Task1!F:F,Task1!M:M,"ModelYCampaign") -> 185071 | E3: =AVERAGEIFS(Task1!F:F,Task1!M:M,"ModelYCampaign") -> 2721.6324 | F3: =SUMIFS(Task1!K:K,Task1!M:M,"ModelYCampaign") -> 11168 | G3: =AVERAGEIFS(Task1!K:K,Task1!M:M,"ModelYCampaign") -> 164.23529
A4: FSDUpdate | B4: =SUMIFS(Task1!I:I,Task1!M:M,"FSDUpdate") -> 2507489 | C4: =AVERAGEIFS(Task1!I:I,Task1!M:M,"FSDUpdate") -> 32993.276 | D4: =SUMIFS(Task1!F:F,Task1!M:M,"FSDUpdate") -> 201400 | E4: =AVERAGEIFS(Task1!F:F,Task1!M:M,"FSDUpdate") -> 2650 | F4: =SUMIFS(Task1!K:K,Task1!M:M,"FSDUpdate") -> 11039 | G4: =AVERAGEIFS(Task1!K:K,Task1!M:M,"FSDUpdate") -> 145.25
A5: SustainabilityDrive | B5: =SUMIFS(Task1!I:I,Task1!M:M,"SustainabilityDrive") -> 2905567 | C5: =AVERAGEIFS(Task1!I:I,Task1!M:M,"SustainabilityDrive") -> 35871.198 | D5: =SUMIFS(Task1!F:F,Task1!M:M,"SustainabilityDrive") -> 219562 | E5: =AVERAGEIFS(Task1!F:F,Task1!M:M,"SustainabilityDrive") -> 2710.642 | F5: =SUMIFS(Task1!K:K,Task1!M:M,"SustainabilityDrive") -> 12544 | G5: =AVERAGEIFS(Task1!K:K,Task1!M:M,"SustainabilityDrive") -> 154.8642
A7: Row Labels | B7: Sum of Total impressions | C7: Sum of Avg Clicks | D7: Sum of Avg Impressions | E7: Sum of Total Likes | F7: Sum of Total Clicks | G7: Sum of Avg Likes
A8: SustainabilityDrive | B8: 2905567 | C8: 154.8642 | D8: 35871.198 | E8: 219562 | F8: 12544 | G8: 2710.642
A9: FSDUpdate | B9: 2507489 | C9: 145.25 | D9: 32993.276 | E9: 201400 | F9: 11039 | G9: 2650
A10: ModelYCampaign | B10: 2318527 | C10: 164.23529 | D10: 34095.985 | E10: 185071 | F10: 11168 | G10: 2721.6324
A11: CybertruckLaunch | B11: 2090555 | C11: 133.84906 | D11: 39444.434 | E11: 154613 | F11: 7094 | G11: 2917.2264
A13: #Insights : SustainabilityDrive campaign has the best impacts among campaign
A16: Campaign Name | B16: Before Campaign | C16: During Campaign | D16: Uplift %
A17: CybertruckLaunch | B17: =AVERAGEIFS(Task1!I:I,Task1!Q:Q,"Before",Task1!M:M,"CybertruckLaunch") -> 13148.5 | C17: =AVERAGEIFS(Task1!I:I,Task1!Q:Q,"During",Task1!M:M,"CybertruckLaunch") -> 40475.647 | D17: =(C17-B17)/B17 -> 2.0783471
A18: ModelYCampaign | B18: =AVERAGEIFS(Task1!I:I,Task1!Q:Q,"Before",Task1!M:M,"ModelYCampaign") -> 34591.208 | C18: =AVERAGEIFS(Task1!I:I,Task1!Q:Q,"During",Task1!M:M,"ModelYCampaign") -> 33825.864 | D18: =(C18-B18)/B18 -> -0.022125411
A19: FSDUpdate | B19: =AVERAGEIFS(Task1!I:I,Task1!Q:Q,"Before",Task1!M:M,"FSDUpdate") -> 30890.16 | C19: =AVERAGEIFS(Task1!I:I,Task1!Q:Q,"During",Task1!M:M,"FSDUpdate") -> 37037.731 | D19: =(C19-B19)/B19 -> 0.19901389
A20: SustainabilityDrive | B20: =AVERAGEIFS(Task1!I:I,Task1!Q:Q,"Before",Task1!M:M,"SustainabilityDrive") -> 37212.183 | C20: =AVERAGEIFS(Task1!I:I,Task1!Q:Q,"During",Task1!M:M,"SustainabilityDrive") -> 32039.81 | D20: =(C20-B20)/B20 -> -0.13899678
A22: #Insights : CybertruckLaunch has highest spike of 208%
A27: Row Labels | B27: Average of ROI
A28: CybertruckLaunch | B28: 0.32619268
A29: ModelYCampaign | B29: 0.32444997
A30: FSDUpdate | B30: 0.310299
A31: NA | B31: 0.29908947
A32: SustainabilityDrive | B32: 0.27131044
A34: #Insights : CybertruckLaunch has the highest ROI
A39: Row Labels | B39: Sum of Growth Rate
A40: SustainabilityDrive | B40: 0.56167728
A41: ModelYCampaign | B41: 0.44877895
A42: CybertruckLaunch | B42: 0.22517317
A43: FSDUpdate | B43: 0.16972346
A45: #Insights : SustainabilityDrive Campaign have the strongest followers growth rate

Sheet Task 6
A3: Row Labels | B3: Sum of Net Growth Followers
A4: 45656 | B4: 6530
A5: Facebook | B5: 1776
A6: Instagram | B6: 1765
A7: Twitter | B7: 1529
A8: YouTube | B8: 1460
A9: 45698 | B9: 5281
A10: Instagram | B10: 1723
A11: YouTube | B11: 1444
A12: Twitter | B12: 1202
A13: Facebook | B13: 912
A14: 45642 | B14: 5044
A15: Instagram | B15: 1432
A16: Facebook | B16: 1377
A17: Twitter | B17: 1359 | D17: #Findings 30 December 2024 week have the highest peak of follower gain
A18: YouTube | B18: 876
A19: 45712 | B19: 4806
A20: Facebook | B20: 1707
A21: Instagram | B21: 1375
A22: YouTube | B22: 1016
A23: Twitter | B23: 708
A24: 45628 | B24: 4795
A25: Facebook | B25: 1706
A26: Instagram | B26: 1625
A27: Twitter | B27: 1173
A28: YouTube | B28: 291
A29: 45635 | B29: 4792
A30: Twitter | B30: 1727
A31: Facebook | B31: 1373
A32: Instagram | B32: 1119
A33: YouTube | B33: 573
A34: 45782 | B34: 4594
A35: Instagram | B35: 1881
A36: Twitter | B36: 1510
A37: YouTube | B37: 864
A38: Facebook | B38: 339
A39: 45600 | B39: 4584
A40: Twitter | B40: 1603
A41: Instagram | B41: 1397
A42: YouTube | B42: 1044
...
